Workbook

Sheet Character Sheet
BI1: 0 | BJ1: -2
B2: Basic Info | O2: ="Attribute Values (Base Total:"&R4+R5+R6+R7+AC4+AC5+AC6+AC7&")" -> Attribute Values (Base Total:0) | AL2: Portrait | AX2: Digestion | BE2: Damage Bonus | BI2: 1 | BJ2: -1
B3: Name | O3: Name | R3: Base | T3: Beyonder | V3: Adjustment | X3: Final | Z3: Name | AC3: Base | AE3: Beyonder | AG3: Adjustment | AI3: Final | AX3: Sequence | AZ3: Digestion % | BB3: Characteristics | BE3: Strength (STR) | BG3: Value | BI3: 2 | BJ3: 0
B4: Player | H4: Race | O4: Strength (STR) | T4: =SUM(AA12:AJ12) -> 0 | X4: =R4+T4+V4+BI58 -> 0 | Z4: Charisma (CHA) | AE4: =SUM(AA16:AJ16) -> 0 | AI4: =AC4+AE4+AG4 -> 0 | AX4: Sequence 9 | BE4: 0 | BG4: -2 | BI4: 3 | BJ4: 1
B5: Age | H5: Gender | O5: Agility (DEX) | T5: =SUM(AA13:AJ13) -> 0 | X5: =R5+T5+V5+BI58 -> 0 | Z5: Intuition (INT) | AE5: =SUM(AA17:AJ17) -> 0 | AI5: =AC5+AE5+AG5 -> 0 | AX5: Sequence 8 | BE5: 1 | BG5: -1 | BI5: 4 | BJ5: 1D2
B6: Occupation | H6: Rank | K6: Mortal | O6: Willpower (WIL) | T6: =SUM(AA14:AJ14) -> 0 | X6: =R6+T6+V6 -> 0 | Z6: Luck | AE6: =SUM(AA18:AJ18) -> 0 | AI6: =AC6+AE6+AG6 -> 0 | AX6: Sequence 7 | BE6: 2 | BG6: 0 | BI6: 5 | BJ6: 1D4
B7: Pathway | H7: Sequence | K7: None | O7: Constitution (CON) | T7: =SUM(AA15:AJ15) -> 0 | X7: =R7+T7+V7 -> 0 | Z7: Education | AE7: =SUM(AA19:AJ19) -> 0 | AI7: =AC7+AE7+AG7 -> 0 | AX7: Sequence 6 | BE7: 3 | BG7: 1 | BI7: 6 | BJ7: 1D6
AX8: Sequence 5 | BE8: 4 | BG8: 1D2 | BI8: 7 | BJ8: 1D8
B9: Vitality | I9: Spirituality | P9: Defense | Y9: Beyonder Attributes | AX9: Sequence 4 | BE9: 5 | BG9: 1D4 | BI9: 8 | BJ9: 1D10
B10: =Tables!V7+D13-D12 -> 10 | E10: ="/"&Tables!V7+D13 -> /10 | I10: =Tables!V6+K13-K12 -> 0 | L10: ="/"&Tables!V6+K13 -> /0 | P10: Physics | R10: =10+X5+R17+Tables!A21+G45+V10 -> 12 | T10: Extra | V10: 0 | Y10: Sequence | AA10: 9 | AB10: 8 | AC10: 7 | AD10: 6 | AE10: 5 | AF10: 4 | AG10: 3 | AH10: 2 | AI10: 1 | AJ10: 0 | AX10: Sequence 3 | BE10: 6 | BG10: 1D6 | BI10: 9 | BJ10: 1D12
P11: Willpower (WIL) | R11: =10+X6+V11 -> 10 | T11: Extra | V11: 0 | AX11: Sequence 2 | BE11: 7 | BG11: 1D8 | BI11: 10 | BJ11: 2D6
B12: Cost | D12: 0 | I12: Cost | K12: 0 | P12: Resilience | R12: =10+R7+V12 -> 10 | T12: Extra | V12: 0 | Y12: Strength (STR) | AX12: Sequence 1 | BE12: 8 | BG12: 1D10 | BI12: 11 | BJ12: 2D8
B13: Extra | D13: 0 | I13: Extra | K13: 0 | P13: Ignore Armor | R13: =10+X5+V10+G45+Tables!A21 -> 12 | T13: Ignore Dodge | V13: =10+R17+V10 -> 10 | Y13: Agility (DEX) | AX13: Sequence 0 | BE13: 9 | BG13: 1D12 | BI13: 12 | BJ13: 2D10
Y14: Willpower (WIL) | BE14: 10 | BG14: 2D6 | BI14: 13 | BJ14: 2D12
B15: Sanity / Rationality | I15: Luck | P15: Other Notes | Y15: Constitution (CON) | AX15: Damage Bonus | BE15: 11 | BG15: 2D8 | BI15: 14 | BJ15: 3D8
B16: =10+X6+D19-D18 -> 10 | E16: ="/"&X6+10+D19 -> /10 | I16: =AI6+K19-K18 -> 0 | L16: ="/"&AI6+K19 -> /0 | P16: Movement | R16: =X4+X5+V16 -> 0 | T16: Extra | V16: 0 | Y16: Charisma (CHA) | AX16: Beyonder Strength Beyond Limits | BE16: 12 | BG16: 2D10 | BI16: 15 | BJ16: 3D10
P17: Armor | R17: 0 | Y17: Intuition (INT) | AX17: 20 | BA17: 3D12 | BE17: 13 | BG17: 2D12 | BI17: 20 | BJ17: 3D12
B18: Cost | D18: 0 | I18: Cost | K18: 0 | P18: Damage Bonus | S18: =VLOOKUP(X4,BI1:BJ19,2,FALSE) -> -2 | Y18: Luck | AX18: 25 | BA18: 4D10 | BE18: 14 | BG18: 3D8 | BI18: 25 | BJ18: 4D10
B19: Extra | D19: 0 | I19: Extra | K19: 0 | P19: Demi-Mythical Creature Mode | T19: × | Y19: Education | AX19: 30 | BA19: 4D12 | BE19: 15 | BG19: 3D10 | BI19: 30 | BJ19: 4D12
B21: Skills | BE21: Knowledge
B22: ="Strength:"&X4 -> Strength:0 | T22: ="Charisma:"&AI4 -> Charisma:0 | AL22: ="Education:"&AI7 -> Education:0 | BE22: Law
B23: Skill | G23: Education | I23: Intuition (INT) | K23: Extra | M23: Proficiency | O23: Roll | R23: Adjustment | T23: Skill | Y23: Education | AA23: Intuition (INT) | AC23: Extra | AE23: Proficiency | AG23: Roll | AJ23: Adjustment | AL23: Skill | AQ23: Education | AS23: Intuition (INT) | AU23: Extra | AW23: Proficiency | AY23: Roll | BB23: Adjustment | BE23: Archaeology
B24: Climbing | M24: =IF(BJ24>6,"Master",VLOOKUP(BJ24,AD48:BH55,2,FALSE)) -> Untrained | O24: ="D20"&Tables!T2&Tables!I1 -> D20-4 | T24: Charm | AE24: =IF(BK24>6,"Master",VLOOKUP(BK24,AD48:BH55,2,FALSE)) -> Untrained | AG24: ="D20"&Tables!T6&Tables!J1 -> D20-4 | AL24: Navigation | AW24: =IF(BL24>6,"Master",VLOOKUP(BL24,AD48:BH55,2,FALSE)) -> Untrained | AY24: ="D20"&Tables!T9&Tables!K1 -> D20-4 | BE24: Religion | BJ24: =G24+I24+K24 -> 0 | BK24: =Y24+AA24+AC24 -> 0 | BL24: =AQ24+AS24+AU24 -> 0
B25: Throwing | M25: =IF(BJ25>6,"Master",VLOOKUP(BJ25,AD48:BH55,2,FALSE)) -> Untrained | O25: ="D20"&Tables!T2&Tables!I2 -> D20-4 | T25: Deception | AE25: =IF(BK25>6,"Master",VLOOKUP(BK25,AD48:BH55,2,FALSE)) -> Untrained | AG25: ="D20"&Tables!T6&Tables!J2 -> D20-4 | AL25: Trade | AW25: =IF(BL25>6,"Master",VLOOKUP(BL25,AD48:BH55,2,FALSE)) -> Untrained | AY25: ="D20"&Tables!T9&Tables!K2 -> D20-4 | BE25: Chemistry | BJ25: =G25+I25+K25 -> 0 | BK25: =Y25+AA25+AC25 -> 0 | BL25: =AQ25+AS25+AU25 -> 0
B26: Fighting: | E26: Melee | M26: =IF(BJ26>6,"Master",VLOOKUP(BJ26,AD48:BH55,2,FALSE)) -> Untrained | O26: ="D20"&Tables!T2&Tables!I3 -> D20-4 | T26: Fast Talk | AE26: =IF(BK26>6,"Master",VLOOKUP(BK26,AD48:BH55,2,FALSE)) -> Untrained | AG26: ="D20"&Tables!T6&Tables!J3 -> D20-4 | AL26: Medicine | AW26: =IF(BL26>6,"Master",VLOOKUP(BL26,AD48:BH55,2,FALSE)) -> Untrained | AY26: ="D20"&Tables!T9&Tables!K3 -> D20-4 | BE26: Biology | BJ26: =G26+I26+K26 -> 0 | BK26: =Y26+AA26+AC26 -> 0 | BL26: =AQ26+AS26+AU26 -> 0
B27: Fighting: | M27: =IF(BJ27>6,"Master",VLOOKUP(BJ27,AD48:BH55,2,FALSE)) -> Untrained | O27: ="D20"&Tables!T2&Tables!I4 -> D20-4 | T27: Persuade | AE27: =IF(BK27>6,"Master",VLOOKUP(BK27,AD48:BH55,2,FALSE)) -> Untrained | AG27: ="D20"&Tables!T6&Tables!J4 -> D20-4 | AL27: Library Use | AW27: =IF(BL27>6,"Master",VLOOKUP(BL27,AD48:BH55,2,FALSE)) -> Untrained | AY27: ="D20"&Tables!T9&Tables!K4 -> D20-4 | BE27: Pharmacy | BJ27: =G27+I27+K27 -> 0 | BK27: =Y27+AA27+AC27 -> 0 | BL27: =AQ27+AS27+AU27 -> 0
B28: Fighting: | M28: =IF(BJ28>6,"Master",VLOOKUP(BJ28,AD47:AN55,2,FALSE)) -> Untrained | O28: ="D20"&Tables!T2&Tables!I5 -> D20-4 | T28: Psychoanalysis | AE28: =IF(BK28>6,"Master",VLOOKUP(BK28,AD48:BH55,2,FALSE)) -> Untrained | AG28: ="D20"&Tables!T6&Tables!J5 -> D20-4 | AL28: Writing | AW28: =IF(BL28>6,"Master",VLOOKUP(BL28,AD48:BH55,2,FALSE)) -> Untrained | AY28: ="D20"&Tables!T9&Tables!K5 -> D20-4 | BE28: Sociology | BJ28: =G28+I28+K28 -> 0 | BK28: =Y28+AA28+AC28 -> 0 | BL28: =AQ28+AS28+AU28 -> 0
B29: Intimidation | M29: =IF(BJ29>6,"Master",VLOOKUP(BJ29,AD48:AE55,2,FALSE)) -> Untrained | O29: ="D20"&Tables!T2&Tables!I6 -> D20-4 | T29: Performance | AE29: =IF(BK29>6,"Master",VLOOKUP(BK29,AD48:BH55,2,FALSE)) -> Untrained | AG29: ="D20"&Tables!T6&Tables!J6 -> D20-4 | AL29: Demolitions | AW29: =IF(BL29>6,"Master",VLOOKUP(BL29,AD48:BH55,2,FALSE)) -> Untrained | AY29: ="D20"&Tables!T9&Tables!K6 -> D20-4 | BE29: Astronomy | BJ29: =G29+I29+K29 -> 0 | BK29: =Y29+AA29+AC29 -> 0 | BL29: =AQ29+AS29+AU29 -> 0
B30: Jumping | M30: =IF(BJ30>6,"Master",VLOOKUP(BJ30,AD48:BH55,2,FALSE)) -> Untrained | O30: ="D20"&Tables!T2&Tables!I7 -> D20-4 | T30: Disguise | AE30: =IF(BK30>6,"Master",VLOOKUP(BK30,AD48:BH55,2,FALSE)) -> Untrained | AG30: ="D20"&Tables!T6&Tables!J7 -> D20-4 | AL30: Survival | AW30: =IF(BL30>6,"Master",VLOOKUP(BL30,AD48:BH55,2,FALSE)) -> Untrained | AY30: ="D20"&Tables!T9&Tables!K7 -> D20-4 | BE30: Botany | BJ30: =G30+I30+K30 -> 0 | BK30: =Y30+AA30+AC30 -> 0 | BL30: =AQ30+AS30+AU30 -> 0
B31: Animal Handling | M31: =IF(BJ31>6,"Master",VLOOKUP(BJ31,AD48:BH55,2,FALSE)) -> Untrained | O31: ="D20"&Tables!T2&Tables!I8 -> D20-4 | T31: Reputation | AE31: =IF(BK31>6,"Master",VLOOKUP(BK31,AD48:BH55,2,FALSE)) -> Untrained | AG31: ="D20"&Tables!T6&Tables!J8 -> D20-4 | AL31: Natural World | AW31: =IF(BL31>6,"Master",VLOOKUP(BL31,AD48:BH55,2,FALSE)) -> Untrained | AY31: ="D20"&Tables!T9&Tables!K8 -> D20-4 | BE31: Agriculture | BJ31: =G31+I31+K31 -> 0 | BK31: =Y31+AA31+AC31 -> 0 | BL31: =AQ31+AS31+AU31 -> 0
B32: ="Agility:"&X5 -> Agility:0 | T32: ="Intuition:"&AI5 -> Intuition:0 | AL32: Knowledge: | AW32: =IF(BL32>6,"Master",VLOOKUP(BL32,AD48:BH55,2,FALSE)) -> Untrained | AY32: ="D20"&Tables!T9&Tables!K9 -> D20-4 | BE32: History | BL32: =AQ32+AS32+AU32 -> 0
B33: Skill | G33: Education | I33: Intuition (INT) | K33: Extra | M33: Proficiency | O33: Roll | R33: Adjustment | T33: Skill | Y33: Education | AA33: Intuition (INT) | AC33: Extra | AE33: Proficiency | AG33: Roll | AJ33: Adjustment | AL33: Knowledge: | AW33: =IF(BL33>6,"Master",VLOOKUP(BL33,AD48:BH55,2,FALSE)) -> Untrained | AY33: ="D20"&Tables!T9&Tables!K10 -> D20-4 | BE33: Engineering | BL33: =AQ33+AS33+AU33 -> 0
B34: Stealth | M34: =IF(BJ34>6,"Master",VLOOKUP(BJ34,AD48:BH55,2,FALSE)) -> Untrained | O34: ="D20"&Tables!T3&Tables!I11 -> D20-4 | T34: Listen | AE34: =IF(BK34>6,"Master",VLOOKUP(BK34,AD48:BH55,2,FALSE)) -> Untrained | AG34: ="D20"&Tables!T7&Tables!J11 -> D20-4 | AL34: Knowledge: | AW34: =IF(BL34>6,"Master",VLOOKUP(BL34,AD48:BH55,2,FALSE)) -> Untrained | AY34: ="D20"&Tables!T9&Tables!K11 -> D20-4 | BJ34: =G34+I34+K34 -> 0 | BK34: =Y34+AA34+AC34 -> 0 | BL34: =AQ34+AS34+AU34 -> 0
B35: Sleight of Hand | M35: =IF(BJ35>6,"Master",VLOOKUP(BJ35,AD48:BH55,2,FALSE)) -> Untrained | O35: ="D20"&Tables!T3&Tables!I12 -> D20-4 | T35: Investigation | AE35: =IF(BK35>6,"Master",VLOOKUP(BK35,AD48:AE55,2,FALSE)) -> Untrained | AG35: ="D20"&Tables!T7&Tables!J12 -> D20-4 | AL35: Knowledge: | AW35: =IF(BL35>6,"Master",VLOOKUP(BL35,AD48:BH55,2,FALSE)) -> Untrained | AY35: ="D20"&Tables!T9&Tables!K12 -> D20-4 | BJ35: =G35+I35+K35 -> 0 | BK35: =Y35+AA35+AC35 -> 0 | BL35: =AQ35+AS35+AU35 -> 0
B36: Swimming | M36: =IF(BJ36>6,"Master",VLOOKUP(BJ36,AD48:BH55,2,FALSE)) -> Untrained | O36: ="D20"&Tables!T3&Tables!I13 -> D20-4 | T36: Mechanical Repair | AE36: =IF(BK36>6,"Master",VLOOKUP(BK36,AD48:BH55,2,FALSE)) -> Untrained | AG36: ="D20"&Tables!T7&Tables!J13 -> D20-4 | AL36: Knowledge: | AW36: =IF(BL36>6,"Master",VLOOKUP(BL36,AD48:BH55,2,FALSE)) -> Untrained | AY36: ="D20"&Tables!T9&Tables!K13 -> D20-4 | BJ36: =G36+I36+K36 -> 0 | BK36: =Y36+AA36+AC36 -> 0 | BL36: =AQ36+AS36+AU36 -> 0
B37: Shooting: | M37: =IF(BJ37>6,"Master",VLOOKUP(BJ37,AD48:BH55,2,FALSE)) -> Untrained | O37: ="D20"&Tables!T3&Tables!I14 -> D20-4 | T37: Mysticism | AE37: =IF(BK37>6,"Master",VLOOKUP(BK37,AD48:BH55,2,FALSE)) -> Untrained | AG37: ="D20"&Tables!T7&Tables!J14 -> D20-4 | AL37: Knowledge: | AW37: =IF(BL37>6,"Master",VLOOKUP(BL37,AD48:BH55,2,FALSE)) -> Untrained | AY37: ="D20"&Tables!T9&Tables!K14 -> D20-4 | BJ37: =G37+I37+K37 -> 0 | BK37: =Y37+AA37+AC37 -> 0 | BL37: =AQ37+AS37+AU37 -> 0
B38: Shooting: | M38: =IF(BJ38>6,"Master",VLOOKUP(BJ38,AD48:BH55,2,FALSE)) -> Untrained | O38: ="D20"&Tables!T3&Tables!I15 -> D20-4 | T38: Psychology | AE38: =IF(BK38>6,"Master",VLOOKUP(BK38,AD48:BH55,2,FALSE)) -> Untrained | AG38: ="D20"&Tables!T7&Tables!J15 -> D20-4 | AL38: Mystic Languages: | AW38: =IF(BL38>6,"Master",VLOOKUP(BL38,AD48:BH55,2,FALSE)) -> Untrained | AY38: ="D20"&Tables!T9&Tables!K15 -> D20-4 | BJ38: =G38+I38+K38 -> 0 | BK38: =Y38+AA38+AC38 -> 0 | BL38: =AQ38+AS38+AU38 -> 0
B39: Shooting: | M39: =IF(BJ39>6,"Master",VLOOKUP(BJ39,AD48:BH55,2,FALSE)) -> Untrained | O39: ="D20"&Tables!T3&Tables!I16 -> D20-4 | T39: Cooking | AE39: =IF(BK39>6,"Master",VLOOKUP(BK39,AD48:BH55,2,FALSE)) -> Untrained | AG39: ="D20"&Tables!T7&Tables!J16 -> D20-4 | AL39: Mystic Languages: | AW39: =IF(BL39>6,"Master",VLOOKUP(BL39,AD48:BH55,2,FALSE)) -> Untrained | AY39: ="D20"&Tables!T9&Tables!K16 -> D20-4 | BJ39: =G39+I39+K39 -> 0 | BK39: =Y39+AA39+AC39 -> 0 | BL39: =AQ39+AS39+AU39 -> 0
B40: Artillery | M40: =IF(BJ40>6,"Master",VLOOKUP(BJ40,AD48:BH55,2,FALSE)) -> Untrained | O40: ="D20"&Tables!T3&Tables!I17 -> D20-4 | T40: Art: | AE40: =IF(BK40>6,"Master",VLOOKUP(BK40,AD48:BH55,2,FALSE)) -> Untrained | AG40: ="D20"&Tables!T7&Tables!J17 -> D20-4 | AL40: Mystic Languages: | AW40: =IF(BL40>6,"Master",VLOOKUP(BL40,AD48:BH55,2,FALSE)) -> Untrained | AY40: ="D20"&Tables!T9&Tables!K17 -> D20-4 | BJ40: =G40+I40+K40 -> 0 | BK40: =Y40+AA40+AC40 -> 0 | BL40: =AQ40+AS40+AU40 -> 0
B41: Lockpicking | M41: =IF(BJ41>6,"Master",VLOOKUP(BJ41,AD48:BH55,2,FALSE)) -> Untrained | O41: ="D20"&Tables!T3&Tables!I18 -> D20-4 | T41: Art: | AE41: =IF(BK41>6,"Master",VLOOKUP(BK41,AD48:BH55,2,FALSE)) -> Untrained | AG41: ="D20"&Tables!T7&Tables!J18 -> D20-4 | AL41: Mystic Languages: | AW41: =IF(BL41>6,"Master",VLOOKUP(BL41,AD48:BH55,2,FALSE)) -> Untrained | AY41: ="D20"&Tables!T9&Tables!K18 -> D20-4 | BJ41: =G41+I41+K41 -> 0 | BK41: =Y41+AA41+AC41 -> 0 | BL41: =AQ41+AS41+AU41 -> 0
...

Sheet Beyonder Abilities
B2: Extraordinary Abilities (write freely; overflow is OK) | E2: NPC Companions (messenger, blood servant, marionette, avatar, etc.) | G2: Custom Spells (rituals, cantrips, etc.) | I2: Grazed Souls | K2: Recorded (Stolen) Abilities
B3: Sequence | C3: Ability Details | E3: Details | G3: Details | I3: Details | K3: Details
B4: Sequence 9
B5: Sequence 8
B6: Sequence 7
B7: Sequence 6
B8: Sequence 5
B9: Sequence 4
B10: Sequence 3
B11: Sequence 2
B12: Sequence 1
B13: Sequence 0

Sheet Adventure Log
B2: Adventure | C2: KP / GM / Keeper | D2: Party Members | E2: Gains

Sheet Glossary
A1: Chinese (Canonical) | B1: Chinese (Sheet) | C1: English | D1: Notes | F1: retad
A2: 主体信息 | B2: 主体信息 | C2: Character Sheet | D2: Main character sheet: stats, skills, inventory. | F2: =IF(A2<>B2,"Different","Same") -> Same
A3: 超凡能力 | B3: 超凡能力 | C3: Beyonder Abilities | D3: Supernatural abilities and extra powers. | F3: =IF(A3<>B3,"Different","Same") -> Same
A4: 经历模组 | B4: 经历模组 | C4: Adventure Log | D4: Record completed modules/adventures. | F4: =IF(A4<>B4,"Different","Same") -> Same
A5: 附表 | B5: 附表 | C5: Tables | D5: Helper tables & formulas — avoid editing. | F5: =IF(A5<>B5,"Different","Same") -> Same
A6: 一般只有20苏勒，甚至身无分文。 | B6: 一般只有20苏勒，甚至身无分文。 | C6: Poor — only ~20 suleys, or even penniless. | F6: =IF(A6<>B6,"Different","Same") -> Same
A7: 上限 | B7: 上限 | C7: Max | F7: =IF(A7<>B7,"Different","Same") -> Same
A8: 个人财富 | B8: 个 人 财 富 | C8: Personal Wealth | D8: Sheet styling: 个 人 财 富 | F8: =IF(A8<>B8,"Different","Same") -> Different
A9: 中 | B9: 中 | C9: Mid | F9: =IF(A9<>B9,"Different","Same") -> Same
A10: 乐理 | B10: 乐理 | C10: Music Theory | F10: =IF(A10<>B10,"Different","Same") -> Same
A11: 乔装 | B11: 乔装 | C11: Disguise | F11: =IF(A11<>B11,"Different","Same") -> Same
A12: 人设信息 | B12: 人设信息 | C12: Character Concept | F12: =IF(A12<>B12,"Different","Same") -> Same
A13: 仆从 | B13: 仆从 | C13: Servants | F13: =IF(A13<>B13,"Different","Same") -> Same
A14: 仆从/伙伴（信使、血仆、密偶、分身等） | B14: 仆从/伙伴（信使、血仆、密偶、分身等） | C14: NPC Companions (messenger, blood servant, marionette, avatar, etc.) | F14: =IF(A14<>B14,"Different","Same") -> Same
A15: 伤口与疤痕 | B15: 伤口与疤痕 | C15: Wounds & Scars | F15: =IF(A15<>B15,"Different","Same") -> Same
A16: 伤害加值 | B16: 伤害加值 | C16: Damage Bonus | F16: =IF(A16<>B16,"Different","Same") -> Same
A17: 位格 | B17: 位 格 | C17: Rank | D17: Sheet styling: 位 格 In sheet: Rank / Status / Rank (standardize for rulebook continuity) | F17: =IF(A17<>B17,"Different","Same") -> Different
A18: 位格 | B18: 位 格 | C18: Status / Rank | D18: Sheet styling: 位 格 In sheet: Rank / Status / Rank (standardize for rulebook continuity) | F18: =IF(A18<>B18,"Different","Same") -> Different
A19: 位置 | B19: 位 置 | C19: Location | D19: Sheet styling: 位 置 | F19: =IF(A19<>B19,"Different","Same") -> Different
A20: 低 | B20: 低 | C20: Low | F20: =IF(A20<>B20,"Different","Same") -> Same
A21: 住处 | B21: 住处 | C21: Residence | F21: =IF(A21<>B21,"Different","Same") -> Same
A22: 体质 | B22: 体 质 | C22: Constitution (CON) | D22: Sheet styling: 体 质 | F22: =IF(A22<>B22,"Different","Same") -> Different
A23: 体重 | B23: 体重 | C23: Weight | F23: =IF(A23<>B23,"Different","Same") -> Same
A24: 你拥有 | B24: 你拥有 | C24: You have | F24: =IF(A24<>B24,"Different","Same") -> Same
A25: 你的理论物品携带栏位为 | B25: 你的理论物品携带栏位为 | C25: Your capacity is | F25: =IF(A25<>B25,"Different","Same") -> Same
A26: 使用属性 | B26: 使 用 属 性 | C26: Key Attribute | D26: Sheet styling: 使 用 属 性 | F26: =IF(A26<>B26,"Different","Same") -> Different
A27: 侦查 | B27: 侦查 | C27: Investigation | F27: =IF(A27<>B27,"Different","Same") -> Same
A28: 信仰的神明 | B28: 信仰的神明 | C28: Deity Worshipped | F28: =IF(A28<>B28,"Different","Same") -> Same
A29: 信誉 | B29: 信誉 | C29: Reputation | F29: =IF(A29<>B29,"Different","Same") -> Same
A30: 倍数 | B30: 倍数 | C30: Multiplier | F30: =IF(A30<>B30,"Different","Same") -> Same
A31: 其余内容 | B31: 其 余 内 容 | C31: Other Notes | D31: Sheet styling: 其 余 内 容 | F31: =IF(A31<>B31,"Different","Same") -> Different
A32: 写作 | B32: 写作 | C32: Writing | F32: =IF(A32<>B32,"Different","Same") -> Same
A33: 农业 | B33: 农业 | C33: Agriculture | F33: =IF(A33<>B33,"Different","Same") -> Same
A34: 刀剑 | B34: 刀剑 | C34: Swordsmanship | F34: =IF(A34<>B34,"Different","Same") -> Same
A35: 力量 | B35: 力量 | C35: Strength (STR) | F35: =IF(A35<>B35,"Different","Same") -> Same
A36: 力量: | B36: 力量: | C36: Strength: | F36: =IF(A36<>B36,"Different","Same") -> Same
A37: 加值 | B37: 加 值 | C37: Modifier | D37: Sheet styling: 加 值 | F37: =IF(A37<>B37,"Different","Same") -> Different
A38: 化学 | B38: 化学 | C38: Chemistry | F38: =IF(A38<>B38,"Different","Same") -> Same
A39: 医学 | B39: 医学 | C39: Medicine | F39: =IF(A39<>B39,"Different","Same") -> Same
A40: 半神话生物模式 | B40: 半神话生物模式 | C40: Demi-Mythical Creature Mode | F40: =IF(A40<>B40,"Different","Same") -> Same
...

Sheet Tables
A1: =IF('Character Sheet'!M24=0,"",VLOOKUP('Character Sheet'!M24,A25:D31,3,FALSE)) -> -4 | B1: =IF('Character Sheet'!AE24=0,"",VLOOKUP('Character Sheet'!AE24,A25:D31,3,FALSE)) -> -4 | C1: =IF('Character Sheet'!AW24=0,"",VLOOKUP('Character Sheet'!AW24,A25:D31,3,FALSE)) -> -4 | E1: ='Character Sheet'!R24 -> 0 | F1: ='Character Sheet'!AJ24 -> 0 | G1: ='Character Sheet'!BB24 -> 0 | I1: =IF(A1=0,"",IF(A1+E1>0,"+"&A1+E1,A1+E1)) -> -4 | J1: =IF(B1=0,"",IF(B1+F1>0,"+"&B1+F1,B1+F1)) -> -4 | K1: =IF(C1=0,"",IF(C1+G1>0,"+"&C1+G1,C1+G1)) -> -4 | M1: 0 | N1: 0 | O1: ='Character Sheet'!Q50 -> 0 | P1: =VLOOKUP(O1,M1:N9,2,FALSE) -> 0 | Q1: =IF(P1=0,"",IF(P1>0,"+"&P1,P1)) | R1: =IF('Character Sheet'!V50=0,"",VLOOKUP('Character Sheet'!V50,A23:D31,3,FALSE)) -> 0 | S1: =IF(R1=0,"",IF(R1>0,"+"&R1,R1)) | V1: ='Character Sheet'!R6+'Character Sheet'!AC5 -> 0 | W1: Status / Rank | X1: Sequence | Y1: Value | Z1: Multiplier | AA1: Bonus | AB1: Value A | AC1: Value B | AD1: Value C
A2: =IF('Character Sheet'!M25=0,"",VLOOKUP('Character Sheet'!M25,A25:D31,3,FALSE)) -> -4 | B2: =IF('Character Sheet'!AE25=0,"",VLOOKUP('Character Sheet'!AE25,A25:D31,3,FALSE)) -> -4 | C2: =IF('Character Sheet'!AW25=0,"",VLOOKUP('Character Sheet'!AW25,A25:D31,3,FALSE)) -> -4 | E2: ='Character Sheet'!R25 -> 0 | F2: ='Character Sheet'!AJ25 -> 0 | G2: ='Character Sheet'!BB25 -> 0 | I2: =IF(A2=0,"",IF(A2+E2>0,"+"&A2+E2,A2+E2)) -> -4 | J2: =IF(B2=0,"",IF(B2+F2>0,"+"&B2+F2,B2+F2)) -> -4 | K2: =IF(C2=0,"",IF(C2+G2>0,"+"&C2+G2,C2+G2)) -> -4 | M2: Strength (STR) | N2: ='Character Sheet'!R4+'Character Sheet'!T4+'Character Sheet'!V4 -> 0 | O2: ='Character Sheet'!Q51 -> 0 | P2: =VLOOKUP(O2,M1:N9,2,FALSE) -> 0 | Q2: =IF(P2=0,"",IF(P2>0,"+"&P2,P2)) | R2: =IF('Character Sheet'!V51=0,"",VLOOKUP('Character Sheet'!V51,A23:D31,3,FALSE)) -> 0 | S2: =IF(R2=0,"",IF(R2>0,"+"&R2,R2)) | T2: =IF(N2=0,"",IF(N2>0,"+"&N2,N2)) | V2: ='Character Sheet'!K7 -> None | W2: Mortal | X2: None | Y2: 0 | Z2: 1 | AA2: =N6*Y2 -> 0 | AB2: =(V1+AA2)*Z2 -> 0 | AC2: 0 | AD2: =AB2+AC2 -> 0
A3: =IF('Character Sheet'!M26=0,"",VLOOKUP('Character Sheet'!M26,A25:D31,3,FALSE)) -> -4 | B3: =IF('Character Sheet'!AE26=0,"",VLOOKUP('Character Sheet'!AE26,A25:D31,3,FALSE)) -> -4 | C3: =IF('Character Sheet'!AW26=0,"",VLOOKUP('Character Sheet'!AW26,A25:D31,3,FALSE)) -> -4 | E3: ='Character Sheet'!R26 -> 0 | F3: ='Character Sheet'!AJ26 -> 0 | G3: ='Character Sheet'!BB26 -> 0 | I3: =IF(A3=0,"",IF(A3+E3>0,"+"&A3+E3,A3+E3)) -> -4 | J3: =IF(B3=0,"",IF(B3+F3>0,"+"&B3+F3,B3+F3)) -> -4 | K3: =IF(C3=0,"",IF(C3+G3>0,"+"&C3+G3,C3+G3)) -> -4 | M3: Agility (DEX) | N3: ='Character Sheet'!R5+'Character Sheet'!T5+'Character Sheet'!V5 -> 0 | O3: ='Character Sheet'!Q52 -> 0 | P3: =VLOOKUP(O3,M1:N9,2,FALSE) -> 0 | Q3: =IF(P3=0,"",IF(P3>0,"+"&P3,P3)) | R3: =IF('Character Sheet'!V52=0,"",VLOOKUP('Character Sheet'!V52,A23:D31,3,FALSE)) -> 0 | S3: =IF(R3=0,"",IF(R3>0,"+"&R3,R3)) | T3: =IF(N3=0,"",IF(N3>0,"+"&N3,N3)) | V3: ='Character Sheet'!K6 -> Mortal | W3: Low | X3: 9 | Y3: 1 | Z3: 1 | AA3: =N7*Y3 -> 0 | AB3: =(V1+AA3)*Z3 -> 0 | AC3: 0 | AD3: =AB3+AC3 -> 0
A4: =IF('Character Sheet'!M27=0,"",VLOOKUP('Character Sheet'!M27,A25:D31,3,FALSE)) -> -4 | B4: =IF('Character Sheet'!AE27=0,"",VLOOKUP('Character Sheet'!AE27,A25:D31,3,FALSE)) -> -4 | C4: =IF('Character Sheet'!AW27=0,"",VLOOKUP('Character Sheet'!AW27,A25:D31,3,FALSE)) -> -4 | E4: ='Character Sheet'!R27 -> 0 | F4: ='Character Sheet'!AJ27 -> 0 | G4: ='Character Sheet'!BB27 -> 0 | I4: =IF(A4=0,"",IF(A4+E4>0,"+"&A4+E4,A4+E4)) -> -4 | J4: =IF(B4=0,"",IF(B4+F4>0,"+"&B4+F4,B4+F4)) -> -4 | K4: =IF(C4=0,"",IF(C4+G4>0,"+"&C4+G4,C4+G4)) -> -4 | M4: Willpower (WIL) | N4: ='Character Sheet'!R6+'Character Sheet'!T6+'Character Sheet'!V6 -> 0 | O4: ='Character Sheet'!Q53 -> 0 | P4: =VLOOKUP(O4,M1:N9,2,FALSE) -> 0 | Q4: =IF(P4=0,"",IF(P4>0,"+"&P4,P4)) | R4: =IF('Character Sheet'!V53=0,"",VLOOKUP('Character Sheet'!V53,A23:D31,3,FALSE)) -> 0 | S4: =IF(R4=0,"",IF(R4>0,"+"&R4,R4)) | T4: =IF(N4=0,"",IF(N4>0,"+"&N4,N4)) | V4: =SUM('Character Sheet'!AZ4:BA13)/5 -> 0 | W4: Low | X4: 8 | Y4: 2 | Z4: 1 | AA4: =N7*Y4 -> 0 | AB4: =(V1+AA4)*Z4 -> 0 | AC4: 0 | AD4: =AB4+AC4 -> 0
A5: =IF('Character Sheet'!M28=0,"",VLOOKUP('Character Sheet'!M28,A25:D31,3,FALSE)) -> -4 | B5: =IF('Character Sheet'!AE28=0,"",VLOOKUP('Character Sheet'!AE28,A25:D31,3,FALSE)) -> -4 | C5: =IF('Character Sheet'!AW28=0,"",VLOOKUP('Character Sheet'!AW28,A25:D31,3,FALSE)) -> -4 | E5: ='Character Sheet'!R28 -> 0 | F5: ='Character Sheet'!AJ28 -> 0 | G5: ='Character Sheet'!BB28 -> 0 | I5: =IF(A5=0,"",IF(A5+E5>0,"+"&A5+E5,A5+E5)) -> -4 | J5: =IF(B5=0,"",IF(B5+F5>0,"+"&B5+F5,B5+F5)) -> -4 | K5: =IF(C5=0,"",IF(C5+G5>0,"+"&C5+G5,C5+G5)) -> -4 | M5: Constitution (CON) | N5: ='Character Sheet'!R7+'Character Sheet'!T7+'Character Sheet'!V7 -> 0 | O5: ='Character Sheet'!Q54 -> 0 | P5: =VLOOKUP(O5,M1:N9,2,FALSE) -> 0 | Q5: =IF(P5=0,"",IF(P5>0,"+"&P5,P5)) | R5: =IF('Character Sheet'!V54=0,"",VLOOKUP('Character Sheet'!V54,A23:D31,3,FALSE)) -> 0 | S5: =IF(R5=0,"",IF(R5>0,"+"&R5,R5)) | T5: =IF(N5=0,"",IF(N5>0,"+"&N5,N5)) | U5: ='Character Sheet'!T19 -> × | V5: =INT(V4) -> 0 | W5: Mid | X5: 7 | Y5: 3 | Z5: 1 | AA5: =N7*Y5 -> 0 | AB5: =(V1+AA5)*Z5 -> 0 | AC5: 0 | AD5: =AB5+AC5 -> 0
A6: =IF('Character Sheet'!M29=0,"",VLOOKUP('Character Sheet'!M29,A25:D31,3,FALSE)) -> -4 | B6: =IF('Character Sheet'!AE29=0,"",VLOOKUP('Character Sheet'!AE29,A25:D31,3,FALSE)) -> -4 | C6: =IF('Character Sheet'!AW29=0,"",VLOOKUP('Character Sheet'!AW29,A25:D31,3,FALSE)) -> -4 | E6: ='Character Sheet'!R29 -> 0 | F6: ='Character Sheet'!AJ29 -> 0 | G6: ='Character Sheet'!BB29 -> 0 | I6: =IF(A6=0,"",IF(A6+E6>0,"+"&A6+E6,A6+E6)) -> -4 | J6: =IF(B6=0,"",IF(B6+F6>0,"+"&B6+F6,B6+F6)) -> -4 | K6: =IF(C6=0,"",IF(C6+G6>0,"+"&C6+G6,C6+G6)) -> -4 | M6: Charisma (CHA) | N6: ='Character Sheet'!AC4+'Character Sheet'!AE4+'Character Sheet'!AG4 -> 0 | O6: ='Character Sheet'!Q55 -> 0 | P6: =VLOOKUP(O6,M1:N9,2,FALSE) -> 0 | Q6: =IF(P6=0,"",IF(P6>0,"+"&P6,P6)) | R6: =IF('Character Sheet'!V55=0,"",VLOOKUP('Character Sheet'!V55,A23:D31,3,FALSE)) -> 0 | S6: =IF(R6=0,"",IF(R6>0,"+"&R6,R6)) | T6: =IF(N6=0,"",IF(N6>0,"+"&N6,N6)) | U6: =IF(V2=1,IF(V3="Angel King",AD13,VLOOKUP(V2,X1:AD15,7,FALSE)),IF(V2=0,IF(V3="Old One",AD14,IF(V3="Pillar",AD15,VLOOKUP(V2,X1:AD15,7,FALSE))),VLOOKUP(V2,X1:AD15,7,FALSE)))+V5 -> 0 | V6: =IF(U5="√",U6*2,U6) -> 0 | W6: Mid | X6: 6 | Y6: 4 | Z6: 1 | AA6: =N7*Y6 -> 0 | AB6: =(V1+AA6)*Z6 -> 0 | AC6: 0 | AD6: =AB6+AC6 -> 0
A7: =IF('Character Sheet'!M30=0,"",VLOOKUP('Character Sheet'!M30,A25:D31,3,FALSE)) -> -4 | B7: =IF('Character Sheet'!AE30=0,"",VLOOKUP('Character Sheet'!AE30,A25:D31,3,FALSE)) -> -4 | C7: =IF('Character Sheet'!AW30=0,"",VLOOKUP('Character Sheet'!AW30,A25:D31,3,FALSE)) -> -4 | E7: ='Character Sheet'!R30 -> 0 | F7: ='Character Sheet'!AJ30 -> 0 | G7: ='Character Sheet'!BB30 -> 0 | I7: =IF(A7=0,"",IF(A7+E7>0,"+"&A7+E7,A7+E7)) -> -4 | J7: =IF(B7=0,"",IF(B7+F7>0,"+"&B7+F7,B7+F7)) -> -4 | K7: =IF(C7=0,"",IF(C7+G7>0,"+"&C7+G7,C7+G7)) -> -4 | M7: Inspiration/Intuition (INT) | N7: ='Character Sheet'!AC5+'Character Sheet'!AE5+'Character Sheet'!AG5 -> 0 | O7: ='Character Sheet'!Q56 -> 0 | P7: =VLOOKUP(O7,M1:N9,2,FALSE) -> 0 | Q7: =IF(P7=0,"",IF(P7>0,"+"&P7,P7)) | R7: =IF('Character Sheet'!V56=0,"",VLOOKUP('Character Sheet'!V56,A23:D31,3,FALSE)) -> 0 | S7: =IF(R7=0,"",IF(R7>0,"+"&R7,R7)) | T7: =IF(N7=0,"",IF(N7>0,"+"&N7,N7)) | U7: =(((((((10+'Character Sheet'!R7+IF(V2<=9,SUM(V18:W18),0)+IF(V2<=8,SUM(V18:X18),0)+IF(V2<=7,SUM(V18:Y18),0)+IF(V2<=6,SUM(V18:Z18),0)+IF(V2<=5,SUM(V18:AA18),0)+IF(V2<=4,SUM(V18:AB18)*2,0))*IF(V2<=4,2,1))+IF(V2<=3,SUM(V18:AC18)*2,0)+IF(V2<=2,SUM(V18:AD18)*3,0))*IF(V2<=2,2,1)+IF(V2<=1,SUM(V18:AE18)*3,0))*IF(V3="Angel King",1.5,IF(V3="True God",1.5,IF(V3="Old One",1.5,IF(V3="Pillar",1.5,1))))+IF(V2=0,SUM(V18:AF18)*4,0))*IF(V2=0,2,1))*IF(V3="Old One",3,IF(V3="Pillar",3,1)))*IF(V3="Pillar",4,1)+V5 -> 10 | V7: =IF(U5="√",U7*2,U7) -> 10 | W7: Mid | X7: 5 | Y7: 5 | Z7: 1 | AA7: =N7*Y7 -> 0 | AB7: =(V1+AA7)*Z7 -> 0 | AC7: 0 | AD7: =AB7+AC7 -> 0
A8: =IF('Character Sheet'!M31=0,"",VLOOKUP('Character Sheet'!M31,A25:D31,3,FALSE)) -> -4 | B8: =IF('Character Sheet'!AE31=0,"",VLOOKUP('Character Sheet'!AE31,A25:D31,3,FALSE)) -> -4 | C8: =IF('Character Sheet'!AW31=0,"",VLOOKUP('Character Sheet'!AW31,A25:D31,3,FALSE)) -> -4 | E8: ='Character Sheet'!R31 -> 0 | F8: ='Character Sheet'!AJ31 -> 0 | G8: ='Character Sheet'!BB31 -> 0 | I8: =IF(A8=0,"",IF(A8+E8>0,"+"&A8+E8,A8+E8)) -> -4 | J8: =IF(B8=0,"",IF(B8+F8>0,"+"&B8+F8,B8+F8)) -> -4 | K8: =IF(C8=0,"",IF(C8+G8>0,"+"&C8+G8,C8+G8)) -> -4 | M8: Luck | N8: ='Character Sheet'!AC6+'Character Sheet'!AE6+'Character Sheet'!AG6 -> 0 | O8: ='Character Sheet'!Q57 -> 0 | P8: =VLOOKUP(O8,M1:N9,2,FALSE) -> 0 | Q8: =IF(P8=0,"",IF(P8>0,"+"&P8,P8)) | R8: =IF('Character Sheet'!V57=0,"",VLOOKUP('Character Sheet'!V57,A23:D31,3,FALSE)) -> 0 | S8: =IF(R8=0,"",IF(R8>0,"+"&R8,R8)) | T8: =IF(N8=0,"",IF(N8>0,"+"&N8,N8)) | W8: High | X8: 4 | Y8: 6 | Z8: 2 | AA8: =N7*Y8 -> 0 | AB8: =(V1+AA8)*Z8 -> 0 | AC8: 0 | AD8: =AB8+AC8 -> 0
C9: =IF('Character Sheet'!AW32=0,"",VLOOKUP('Character Sheet'!AW32,A25:D31,3,FALSE)) -> -4 | G9: ='Character Sheet'!BB32 -> 0 | K9: =IF(C9=0,"",IF(C9+G9>0,"+"&C9+G9,C9+G9)) -> -4 | M9: Education | N9: ='Character Sheet'!AC7+'Character Sheet'!AE7+'Character Sheet'!AG7 -> 0 | O9: ='Character Sheet'!Q58 -> 0 | P9: =VLOOKUP(O9,M1:N9,2,FALSE) -> 0 | Q9: =IF(P9=0,"",IF(P9>0,"+"&P9,P9)) | R9: =IF('Character Sheet'!V58=0,"",VLOOKUP('Character Sheet'!V58,A23:D31,3,FALSE)) -> 0 | S9: =IF(R9=0,"",IF(R9>0,"+"&R9,R9)) | T9: =IF(N9=0,"",IF(N9>0,"+"&N9,N9)) | W9: High | X9: 3 | Y9: 7 | Z9: 2 | AA9: =N7*Y9 -> 0 | AB9: =(V1+AA9)*Z9 -> 0 | AC9: 0 | AD9: =AB9+AC9 -> 0
C10: =IF('Character Sheet'!AW33=0,"",VLOOKUP('Character Sheet'!AW33,A25:D31,3,FALSE)) -> -4 | G10: ='Character Sheet'!BB33 -> 0 | K10: =IF(C10=0,"",IF(C10+G10>0,"+"&C10+G10,C10+G10)) -> -4 | O10: ='Character Sheet'!Q59 -> 0 | P10: =VLOOKUP(O10,M1:N9,2,FALSE) -> 0 | Q10: =IF(P10=0,"",IF(P10>0,"+"&P10,P10)) | R10: =IF('Character Sheet'!V59=0,"",VLOOKUP('Character Sheet'!V59,A23:D31,3,FALSE)) -> 0 | S10: =IF(R10=0,"",IF(R10>0,"+"&R10,R10)) | W10: Angel | X10: 2 | Y10: 8 | Z10: 4 | AA10: =N7*Y10 -> 0 | AB10: =(V1+AA10)*Z10 -> 0 | AC10: 0 | AD10: =AB10+AC10 -> 0
A11: =IF('Character Sheet'!M34=0,"",VLOOKUP('Character Sheet'!M34,A25:D31,3,FALSE)) -> -4 | B11: =IF('Character Sheet'!AE34=0,"",VLOOKUP('Character Sheet'!AE34,A25:D31,3,FALSE)) -> -4 | C11: =IF('Character Sheet'!AW34=0,"",VLOOKUP('Character Sheet'!AW34,A25:D31,3,FALSE)) -> -4 | E11: ='Character Sheet'!R34 -> 0 | F11: ='Character Sheet'!AJ34 -> 0 | G11: ='Character Sheet'!BB34 -> 0 | I11: =IF(A11=0,"",IF(A11+E11>0,"+"&A11+E11,A11+E11)) -> -4 | J11: =IF(B11=0,"",IF(B11+F11>0,"+"&B11+F11,B11+F11)) -> -4 | K11: =IF(C11=0,"",IF(C11+G11>0,"+"&C11+G11,C11+G11)) -> -4 | O11: ='Character Sheet'!Q60 -> 0 | P11: =VLOOKUP(O11,M1:N9,2,FALSE) -> 0 | Q11: =IF(P11=0,"",IF(P11>0,"+"&P11,P11)) | R11: =IF('Character Sheet'!V60=0,"",VLOOKUP('Character Sheet'!V60,A23:D31,3,FALSE)) -> 0 | S11: =IF(R11=0,"",IF(R11>0,"+"&R11,R11)) | W11: Angel | X11: 1 | Y11: 9 | Z11: 4 | AA11: =N7*Y11 -> 0 | AB11: =(V1+AA11)*Z11 -> 0 | AC11: 0 | AD11: =AB11+AC11 -> 0
A12: =IF('Character Sheet'!M35=0,"",VLOOKUP('Character Sheet'!M35,A25:D31,3,FALSE)) -> -4 | B12: =IF('Character Sheet'!AE35=0,"",VLOOKUP('Character Sheet'!AE35,A25:D31,3,FALSE)) -> -4 | C12: =IF('Character Sheet'!AW35=0,"",VLOOKUP('Character Sheet'!AW35,A25:D31,3,FALSE)) -> -4 | E12: ='Character Sheet'!R35 -> 0 | F12: ='Character Sheet'!AJ35 -> 0 | G12: ='Character Sheet'!BB35 -> 0 | I12: =IF(A12=0,"",IF(A12+E12>0,"+"&A12+E12,A12+E12)) -> -4 | J12: =IF(B12=0,"",IF(B12+F12>0,"+"&B12+F12,B12+F12)) -> -4 | K12: =IF(C12=0,"",IF(C12+G12>0,"+"&C12+G12,C12+G12)) -> -4 | O12: ='Character Sheet'!Q61 -> 0 | P12: =VLOOKUP(O12,M1:N9,2,FALSE) -> 0 | Q12: =IF(P12=0,"",IF(P12>0,"+"&P12,P12)) | R12: =IF('Character Sheet'!V61=0,"",VLOOKUP('Character Sheet'!V61,A23:D31,3,FALSE)) -> 0 | S12: =IF(R12=0,"",IF(R12>0,"+"&R12,R12)) | W12: God | X12: 0 | Y12: 10 | Z12: 8 | AA12: =N7*Y12 -> 0 | AB12: =(V1+AA12)*Z12 -> 0 | AC12: =AB12/2 -> 0 | AD12: =AB12+AC12 -> 0
A13: =IF('Character Sheet'!M36=0,"",VLOOKUP('Character Sheet'!M36,A25:D31,3,FALSE)) -> -4 | B13: =IF('Character Sheet'!AE36=0,"",VLOOKUP('Character Sheet'!AE36,A25:D31,3,FALSE)) -> -4 | C13: =IF('Character Sheet'!AW36=0,"",VLOOKUP('Character Sheet'!AW36,A25:D31,3,FALSE)) -> -4 | E13: ='Character Sheet'!R36 -> 0 | F13: ='Character Sheet'!AJ36 -> 0 | G13: ='Character Sheet'!BB36 -> 0 | I13: =IF(A13=0,"",IF(A13+E13>0,"+"&A13+E13,A13+E13)) -> -4 | J13: =IF(B13=0,"",IF(B13+F13>0,"+"&B13+F13,B13+F13)) -> -4 | K13: =IF(C13=0,"",IF(C13+G13>0,"+"&C13+G13,C13+G13)) -> -4 | O13: ='Character Sheet'!Q62 -> 0 | P13: =VLOOKUP(O13,M1:N9,2,FALSE) -> 0 | Q13: =IF(P13=0,"",IF(P13>0,"+"&P13,P13)) | R13: =IF('Character Sheet'!V62=0,"",VLOOKUP('Character Sheet'!V62,A23:D31,3,FALSE)) -> 0 | S13: =IF(R13=0,"",IF(R13>0,"+"&R13,R13)) | W13: King | X13: 1 | Y13: 9 | Z13: 4 | AA13: =N7*Y13 -> 0 | AB13: =(V1+AA13)*Z13 -> 0 | AC13: =AB13/2 -> 0 | AD13: =AB13+AC13 -> 0
A14: =IF('Character Sheet'!M37=0,"",VLOOKUP('Character Sheet'!M37,A25:D31,3,FALSE)) -> -4 | B14: =IF('Character Sheet'!AE37=0,"",VLOOKUP('Character Sheet'!AE37,A25:D31,3,FALSE)) -> -4 | C14: =IF('Character Sheet'!AW37=0,"",VLOOKUP('Character Sheet'!AW37,A25:D31,3,FALSE)) -> -4 | E14: ='Character Sheet'!R37 -> 0 | F14: ='Character Sheet'!AJ37 -> 0 | G14: ='Character Sheet'!BB37 -> 0 | I14: =IF(A14=0,"",IF(A14+E14>0,"+"&A14+E14,A14+E14)) -> -4 | J14: =IF(B14=0,"",IF(B14+F14>0,"+"&B14+F14,B14+F14)) -> -4 | K14: =IF(C14=0,"",IF(C14+G14>0,"+"&C14+G14,C14+G14)) -> -4 | O14: ='Character Sheet'!Q63 -> 0 | P14: =VLOOKUP(O14,M1:N9,2,FALSE) -> 0 | Q14: =IF(P14=0,"",IF(P14>0,"+"&P14,P14)) | R14: =IF('Character Sheet'!V63=0,"",VLOOKUP('Character Sheet'!V63,A23:D31,3,FALSE)) -> 0 | S14: =IF(R14=0,"",IF(R14>0,"+"&R14,R14)) | W14: Old | X14: 0 | Y14: 10 | Z14: 24 | AA14: =N7*Y14 -> 0 | AB14: =(V1+AA14)*Z14 -> 0 | AC14: =AB14/2 -> 0 | AD14: =AB14+AC14 -> 0
A15: =IF('Character Sheet'!M38=0,"",VLOOKUP('Character Sheet'!M38,A25:D31,3,FALSE)) -> -4 | B15: =IF('Character Sheet'!AE38=0,"",VLOOKUP('Character Sheet'!AE38,A25:D31,3,FALSE)) -> -4 | C15: =IF('Character Sheet'!AW38=0,"",VLOOKUP('Character Sheet'!AW38,A25:D31,3,FALSE)) -> -4 | E15: ='Character Sheet'!R38 -> 0 | F15: ='Character Sheet'!AJ38 -> 0 | G15: ='Character Sheet'!BB38 -> 0 | I15: =IF(A15=0,"",IF(A15+E15>0,"+"&A15+E15,A15+E15)) -> -4 | J15: =IF(B15=0,"",IF(B15+F15>0,"+"&B15+F15,B15+F15)) -> -4 | K15: =IF(C15=0,"",IF(C15+G15>0,"+"&C15+G15,C15+G15)) -> -4 | O15: ='Character Sheet'!Q64 -> 0 | P15: =VLOOKUP(O15,M1:N9,2,FALSE) -> 0 | Q15: =IF(P15=0,"",IF(P15>0,"+"&P15,P15)) | R15: =IF('Character Sheet'!V64=0,"",VLOOKUP('Character Sheet'!V64,A23:D31,3,FALSE)) -> 0 | S15: =IF(R15=0,"",IF(R15>0,"+"&R15,R15)) | W15: Pillar | X15: 0 | Y15: 10 | Z15: 96 | AA15: =N7*Y15 -> 0 | AB15: =(V1+AA15)*Z15 -> 0 | AC15: =AB15/2 -> 0 | AD15: =AB15+AC15 -> 0
A16: =IF('Character Sheet'!M39=0,"",VLOOKUP('Character Sheet'!M39,A25:D31,3,FALSE)) -> -4 | B16: =IF('Character Sheet'!AE39=0,"",VLOOKUP('Character Sheet'!AE39,A25:D31,3,FALSE)) -> -4 | C16: =IF('Character Sheet'!AW39=0,"",VLOOKUP('Character Sheet'!AW39,A25:D31,3,FALSE)) -> -4 | E16: ='Character Sheet'!R39 -> 0 | F16: ='Character Sheet'!AJ39 -> 0 | G16: ='Character Sheet'!BB39 -> 0 | I16: =IF(A16=0,"",IF(A16+E16>0,"+"&A16+E16,A16+E16)) -> -4 | J16: =IF(B16=0,"",IF(B16+F16>0,"+"&B16+F16,B16+F16)) -> -4 | K16: =IF(C16=0,"",IF(C16+G16>0,"+"&C16+G16,C16+G16)) -> -4 | O16: ='Character Sheet'!Q65 -> 0 | P16: =VLOOKUP(O16,M1:N9,2,FALSE) -> 0 | Q16: =IF(P16=0,"",IF(P16>0,"+"&P16,P16)) | R16: =IF('Character Sheet'!V65=0,"",VLOOKUP('Character Sheet'!V65,A23:D31,3,FALSE)) -> 0 | S16: =IF(R16=0,"",IF(R16>0,"+"&R16,R16))
A17: =IF('Character Sheet'!M40=0,"",VLOOKUP('Character Sheet'!M40,A25:D31,3,FALSE)) -> -4 | B17: =IF('Character Sheet'!AE40=0,"",VLOOKUP('Character Sheet'!AE40,A25:D31,3,FALSE)) -> -4 | C17: =IF('Character Sheet'!AW40=0,"",VLOOKUP('Character Sheet'!AW40,A25:D31,3,FALSE)) -> -4 | E17: ='Character Sheet'!R40 -> 0 | F17: ='Character Sheet'!AJ40 -> 0 | G17: ='Character Sheet'!BB40 -> 0 | I17: =IF(A17=0,"",IF(A17+E17>0,"+"&A17+E17,A17+E17)) -> -4 | J17: =IF(B17=0,"",IF(B17+F17>0,"+"&B17+F17,B17+F17)) -> -4 | K17: =IF(C17=0,"",IF(C17+G17>0,"+"&C17+G17,C17+G17)) -> -4 | O17: ='Character Sheet'!Q66 -> 0 | P17: =VLOOKUP(O17,M1:N9,2,FALSE) -> 0 | Q17: =IF(P17=0,"",IF(P17>0,"+"&P17,P17)) | R17: =IF('Character Sheet'!V66=0,"",VLOOKUP('Character Sheet'!V66,A23:D31,3,FALSE)) -> 0 | S17: =IF(R17=0,"",IF(R17>0,"+"&R17,R17)) | W17: 9 | X17: 8 | Y17: 7 | Z17: 6 | AA17: 5 | AB17: 4 | AC17: 3 | AD17: 2 | AE17: 1 | AF17: 0
A18: =IF('Character Sheet'!M40=0,"",VLOOKUP('Character Sheet'!M40,A25:D31,3,FALSE)) -> -4 | B18: =IF('Character Sheet'!AE40=0,"",VLOOKUP('Character Sheet'!AE40,A25:D31,3,FALSE)) -> -4 | C18: =IF('Character Sheet'!AW41=0,"",VLOOKUP('Character Sheet'!AW41,A25:D31,3,FALSE)) -> -4 | E18: ='Character Sheet'!R41 -> 0 | F18: ='Character Sheet'!AJ41 -> 0 | G18: ='Character Sheet'!BB41 -> 0 | I18: =IF(A18=0,"",IF(A18+E18>0,"+"&A18+E18,A18+E18)) -> -4 | J18: =IF(B18=0,"",IF(B18+F18>0,"+"&B18+F18,B18+F18)) -> -4 | K18: =IF(C18=0,"",IF(C18+G18>0,"+"&C18+G18,C18+G18)) -> -4 | O18: ='Character Sheet'!Q67 -> 0 | P18: =VLOOKUP(O18,M1:N9,2,FALSE) -> 0 | Q18: =IF(P18=0,"",IF(P18>0,"+"&P18,P18)) | R18: =IF('Character Sheet'!V67=0,"",VLOOKUP('Character Sheet'!V67,A23:D31,3,FALSE)) -> 0 | S18: =IF(R18=0,"",IF(R18>0,"+"&R18,R18)) | V18: ='Character Sheet'!R7 -> 0 | W18: ='Character Sheet'!AA15 -> 0 | X18: ='Character Sheet'!AB15 -> 0 | Y18: ='Character Sheet'!AC15 -> 0 | Z18: ='Character Sheet'!AD15 -> 0 | AA18: ='Character Sheet'!AE15 -> 0 | AB18: ='Character Sheet'!AF15 -> 0 | AC18: ='Character Sheet'!AG15 -> 0 | AD18: ='Character Sheet'!AH15 -> 0 | ... AF18: ='Character Sheet'!AJ15 -> 0
A19: =IF('Character Sheet'!M42=0,"",VLOOKUP('Character Sheet'!M42,A25:D31,3,FALSE)) -> -4 | B19: =IF('Character Sheet'!AE42=0,"",VLOOKUP('Character Sheet'!AE42,A25:D31,3,FALSE)) -> -4 | C19: =IF('Character Sheet'!AW42=0,"",VLOOKUP('Character Sheet'!AW42,A25:D31,3,FALSE)) -> -4 | E19: ='Character Sheet'!R42 -> 0 | F19: ='Character Sheet'!AJ42 -> 0 | G19: ='Character Sheet'!BB42 -> 0 | I19: =IF(A19=0,"",IF(A19+E19>0,"+"&A19+E19,A19+E19)) -> -4 | J19: =IF(B19=0,"",IF(B19+F19>0,"+"&B19+F19,B19+F19)) -> -4 | K19: =IF(C19=0,"",IF(C19+G19>0,"+"&C19+G19,C19+G19)) -> -4 | O19: ='Character Sheet'!Q68 -> 0 | P19: =VLOOKUP(O19,M1:N9,2,FALSE) -> 0 | Q19: =IF(P19=0,"",IF(P19>0,"+"&P19,P19)) | R19: =IF('Character Sheet'!V68=0,"",VLOOKUP('Character Sheet'!V68,A23:D31,3,FALSE)) -> 0 | S19: =IF(R19=0,"",IF(R19>0,"+"&R19,R19))
A20: =IF('Character Sheet'!M43=0,"",VLOOKUP('Character Sheet'!M43,A25:D31,3,FALSE)) -> -4 | B20: =IF('Character Sheet'!AE43=0,"",VLOOKUP('Character Sheet'!AE43,A25:D31,3,FALSE)) -> -4 | C20: =IF('Character Sheet'!AW43=0,"",VLOOKUP('Character Sheet'!AW43,A25:D31,3,FALSE)) -> -4 | E20: ='Character Sheet'!R43 -> 0 | F20: ='Character Sheet'!AJ43 -> 0 | G20: ='Character Sheet'!BB43 -> 0 | I20: =IF(A20=0,"",IF(A20+E20>0,"+"&A20+E20,A20+E20)) -> -4 | J20: =IF(B20=0,"",IF(B20+F20>0,"+"&B20+F20,B20+F20)) -> -4 | K20: =IF(C20=0,"",IF(C20+G20>0,"+"&C20+G20,C20+G20)) -> -4 | O20: ='Character Sheet'!Q69 -> 0 | P20: =VLOOKUP(O20,M1:N9,2,FALSE) -> 0 | Q20: =IF(P20=0,"",IF(P20>0,"+"&P20,P20)) | R20: =IF('Character Sheet'!V69=0,"",VLOOKUP('Character Sheet'!V69,A23:D31,3,FALSE)) -> 0 | S20: =IF(R20=0,"",IF(R20>0,"+"&R20,R20))
A21: =IF('Character Sheet'!M44=0,"",VLOOKUP('Character Sheet'!M44,A25:D31,3,FALSE)) -> 2 | B21: =IF('Character Sheet'!AE44=0,"",VLOOKUP('Character Sheet'!AE44,A25:D31,3,FALSE)) -> -4 | C21: =IF('Character Sheet'!AW44=0,"",VLOOKUP('Character Sheet'!AW44,A25:D31,3,FALSE)) -> -4 | E21: ='Character Sheet'!R44 -> 0 | F21: ='Character Sheet'!AJ44 -> 0 | G21: ='Character Sheet'!BB44 -> 0 | I21: =IF(A21=0,"",IF(A21+E21>0,"+"&A21+E21,A21+E21)) -> +2 | J21: =IF(B21=0,"",IF(B21+F21>0,"+"&B21+F21,B21+F21)) -> -4 | K21: =IF(C21=0,"",IF(C21+G21>0,"+"&C21+G21,C21+G21)) -> -4 | O21: ='Character Sheet'!Q70 -> 0 | P21: =VLOOKUP(O21,M1:N9,2,FALSE) -> 0 | Q21: =IF(P21=0,"",IF(P21>0,"+"&P21,P21)) | R21: =IF('Character Sheet'!V70=0,"",VLOOKUP('Character Sheet'!V70,A23:D31,3,FALSE)) -> 0 | S21: =IF(R21=0,"",IF(R21>0,"+"&R21,R21))
C22: =IF('Character Sheet'!AW45=0,"",VLOOKUP('Character Sheet'!AW45,A25:D31,3,FALSE)) -> -4 | G22: ='Character Sheet'!BB45 -> 0 | I22: =IF(A22=0,"",IF(A22>0,"+"&A22,A22)) | J22: =IF(B22=0,"",IF(B22>0,"+"&B22,B22)) | K22: =IF(C22=0,"",IF(C22+G22>0,"+"&C22+G22,C22+G22)) -> -4 | O22: ='Character Sheet'!Q71 -> 0 | P22: =VLOOKUP(O22,M1:N9,2,FALSE) -> 0 | Q22: =IF(P22=0,"",IF(P22>0,"+"&P22,P22)) | R22: =IF('Character Sheet'!V71=0,"",VLOOKUP('Character Sheet'!V71,A23:D31,3,FALSE)) -> 0 | S22: =IF(R22=0,"",IF(R22>0,"+"&R22,R22))
A23: None | C23: 0 | O23: ='Character Sheet'!Q72 -> 0 | P23: =VLOOKUP(O23,M1:N9,2,FALSE) -> 0 | Q23: =IF(P23=0,"",IF(P23>0,"+"&P23,P23)) | R23: =IF('Character Sheet'!V72=0,"",VLOOKUP('Character Sheet'!V72,A23:D31,3,FALSE)) -> 0 | S23: =IF(R23=0,"",IF(R23>0,"+"&R23,R23))
A24: Level | C24: Modifier | E24: Weekly Pay (Roll/Guideline) | F24: Residence (Guideline) | G24: Servants (Guideline) | H24: Weekly Rent (Guideline) | O24: ='Character Sheet'!Q73 -> 0 | P24: =VLOOKUP(O24,M1:N9,2,FALSE) -> 0 | Q24: =IF(P24=0,"",IF(P24>0,"+"&P24,P24)) | R24: =IF('Character Sheet'!V73=0,"",VLOOKUP('Character Sheet'!V73,A23:D31,3,FALSE)) -> 0 | S24: =IF(R24=0,"",IF(R24>0,"+"&R24,R24))
A25: Untrained | C25: -4 | E25: Roll: 20 + 1d20 + 1d20 | F25: No fixed home / makeshift lodging | G25: None | H25: None or minimal
A26: Trained | C26: 2 | E26: Roll: 1d5 + 1d10 (min 3) | F26: Shared room / cheap inn | G26: 0–1 occasional help | H26: Low (basic room/board)
A27: Proficient | C27: 4 | E27: Roll: 1d20 + 2d50 (min 50) | F27: Comfortable apartment / house | G27: 1–2 servants | H27: Moderate
A28: Advanced | C28: 5 | E28: Roll: 2d50 + 4d100 (min 200) | F28: Large home / upscale apartment | G28: 2–4 servants | H28: High
A29: Expert | C29: 6 | E29: Roll: 40d100 + 20d400 (min 1000) | F29: Townhouse / small estate | G29: 5–10 servants | H29: Very high
A30: Scholar | C30: 7 | E30: Roll: 50d200 + 40d500 (min 10000) | F30: Noble estate / manor | G30: 10–20 servants | H30: Estate upkeep
A31: Master | C31: 8 | E31: Roll: 100d500 (min 10000) | F31: Palace / royal estate | G31: 20+ servants | H31: Royal upkeep
